Exception on / [POST]
Traceback (most recent call last):
  File "/home/mb/.local/lib/python3.6/site-packages/flask/app.py", line 2446, in wsgi_app
    response = self.full_dispatch_request()
  File "/home/mb/.local/lib/python3.6/site-packages/flask/app.py", line 1951, in full_dispatch_request
    rv = self.handle_user_exception(e)
  File "/home/mb/.local/lib/python3.6/site-packages/flask/app.py", line 1820, in handle_user_exception
    reraise(exc_type, exc_value, tb)
  File "/home/mb/.local/lib/python3.6/site-packages/flask/_compat.py", line 39, in reraise
    raise value
  File "/home/mb/.local/lib/python3.6/site-packages/flask/app.py", line 1949, in full_dispatch_request
    rv = self.dispatch_request()
  File "/home/mb/.local/lib/python3.6/site-packages/flask/app.py", line 1935, in dispatch_request
    return self.view_functions[rule.endpoint](**req.view_args)
  File "server.py", line 73, in extract_cccd
    file=img_name ))
KeyError: 'date'
2019-10-04 14:52:54 | ocr: 5.jpg
Exception on / [POST]
Traceback (most recent call last):
  File "/home/mb/.local/lib/python3.6/site-packages/flask/app.py", line 2446, in wsgi_app
    response = self.full_dispatch_request()
  File "/home/mb/.local/lib/python3.6/site-packages/flask/app.py", line 1952, in full_dispatch_request
    return self.finalize_request(rv)
  File "/home/mb/.local/lib/python3.6/site-packages/flask/app.py", line 1967, in finalize_request
    response = self.make_response(rv)
  File "/home/mb/.local/lib/python3.6/site-packages/flask/app.py", line 2097, in make_response
    "The view function did not return a valid response. The"
TypeError: The view function did not return a valid response. The function either returned None or ended without a return statement.
2019-10-04 14:53:59 | ocr: 5.jpg
Exception on / [POST]
Traceback (most recent call last):
  File "/home/mb/.local/lib/python3.6/site-packages/flask/app.py", line 2446, in wsgi_app
    response = self.full_dispatch_request()
  File "/home/mb/.local/lib/python3.6/site-packages/flask/app.py", line 1952, in full_dispatch_request
    return self.finalize_request(rv)
  File "/home/mb/.local/lib/python3.6/site-packages/flask/app.py", line 1967, in finalize_request
    response = self.make_response(rv)
  File "/home/mb/.local/lib/python3.6/site-packages/flask/app.py", line 2097, in make_response
    "The view function did not return a valid response. The"
TypeError: The view function did not return a valid response. The function either returned None or ended without a return statement.
Exception on / [POST]
Traceback (most recent call last):
  File "/home/mb/.local/lib/python3.6/site-packages/flask/app.py", line 2446, in wsgi_app
    response = self.full_dispatch_request()
  File "/home/mb/.local/lib/python3.6/site-packages/flask/app.py", line 1951, in full_dispatch_request
    rv = self.handle_user_exception(e)
  File "/home/mb/.local/lib/python3.6/site-packages/flask/app.py", line 1820, in handle_user_exception
    reraise(exc_type, exc_value, tb)
  File "/home/mb/.local/lib/python3.6/site-packages/flask/_compat.py", line 39, in reraise
    raise value
  File "/home/mb/.local/lib/python3.6/site-packages/flask/app.py", line 1949, in full_dispatch_request
    rv = self.dispatch_request()
  File "/home/mb/.local/lib/python3.6/site-packages/flask/app.py", line 1935, in dispatch_request
    return self.view_functions[rule.endpoint](**req.view_args)
  File "server.py", line 66, in extract_cccd
    data = cccd(saved_path)
  File "/home/mb/Desktop/CCCD_detector/flask-api-upload-image/cccd_1.py", line 333, in cccd
    data = merge_img(len(res))
  File "/home/mb/Desktop/CCCD_detector/flask-api-upload-image/cccd_1.py", line 88, in merge_img
    return ocr('prepare_ocr.jpg')
  File "/home/mb/Desktop/CCCD_detector/flask-api-upload-image/drive_ocr.py", line 34, in ocr
    'credentials.json', SCOPES)
  File "/home/mb/.local/lib/python3.6/site-packages/google_auth_oauthlib/flow.py", line 180, in from_client_secrets_file
    with open(client_secrets_file, 'r') as json_file:
FileNotFoundError: [Errno 2] No such file or directory: 'credentials.json'
2019-10-04 14:55:12 | ocr: 5.jpg
Exception on / [POST]
Traceback (most recent call last):
  File "/home/mb/.local/lib/python3.6/site-packages/flask/app.py", line 2446, in wsgi_app
    response = self.full_dispatch_request()
  File "/home/mb/.local/lib/python3.6/site-packages/flask/app.py", line 1952, in full_dispatch_request
    return self.finalize_request(rv)
  File "/home/mb/.local/lib/python3.6/site-packages/flask/app.py", line 1967, in finalize_request
    response = self.make_response(rv)
  File "/home/mb/.local/lib/python3.6/site-packages/flask/app.py", line 2130, in make_response
    " {rv.__class__.__name__}.".format(rv=rv)
TypeError: The view function did not return a valid response. The return type must be a string, dict, tuple, Response instance, or WSGI callable, but it was a list.
2019-10-04 14:56:02 | ocr: 5.jpg
2019-10-04 15:03:28 | ocr: t5.png
2019-10-04 15:04:43 | ocr: 49.jpg
2019-10-04 15:07:05 | ocr: t5.png
2019-10-04 15:07:42 | ocr: t5.png
2019-10-04 15:08:10 | ocr: 5.jpg
2019-10-04 15:08:57 | ocr: 4.jpeg
2019-10-04 15:09:45 | ocr: 23.jpg
2019-10-04 15:11:13 | ocr: 22.jpg
2019-10-04 16:26:28 | ocr: 5.jpg
2019-10-04 16:32:58 | ocr: 5.jpg
